## panic深入剖析

### 不可恢复错误

* 只有不知如何处理才去调用

### 调用panic!

* backtrace栈展开

  * `RUST_BACKTRACE=1 cargo run`

### 两种终止方式

* 栈展开(默认)
* 直接终止

  * 关心最终编译出的二进制可执行文件大小时使用
  * ```toml
    [profile.release]
    panic = 'abort'
    ```

* 程序是否终止

  * main线程会终止
  * 子线程则子线程终止,不影响main线程

### 何时使用

* 直接使用`unwrap`​ 和 `expect`​
* 快速搭建代码时

  * 后期全局替换
* 知道程序是正确时可以使用
* 可能导致全局有害状态时

  * 非预期错误
  * 后续代码显著受影响
  * 内存安全

### 原理

* 格式化panic信息, 使用该信息调用std::panic::panic_any()函数
* 函数检查 panic hook
* hook返回后, 当前线程进行栈展开

  * 寄存器或栈错乱, 导致展开异常, 线程会直接停止
* 展开是一帧一帧回溯, 每帧信息会随之丢弃

  * 遇到被用户标记为 `catching`​ 的帧（通过 `std::panic::catch_unwind()`​ 函数标记），此时用户提供的 `catch`​ 函数会被调用，展开也随之停止

## 可恢复错误 Result

```toml
enum Result<T, E> {
    Ok(T),
    Err(E),
}
```

### 对返回的错误进行处理

```rust
use std::fs::File;
use std::io::ErrorKind;

fn main() {
    let f = File::open("hello.txt");

    let f = match f {
        Ok(file) => file,
        Err(error) => match error.kind() {
            ErrorKind::NotFound => match File::create("hello.txt") {
                Ok(fc) => fc,
                Err(e) => panic!("Problem creating the file: {:?}", e),
            },
            other_error => panic!("Problem opening the file: {:?}", other_error),
        },
    };
}
```

### 传播错误 ?

```rust
fn open_file() -> Result<File, Box<dyn std::error::Error>> {
    let mut f = File::open("hello.txt")?;
    Ok(f)
}
```

```rust

use std::fs::File;
use std::io;
use std::io::Read;

fn read_username_from_file() -> Result<String, io::Error> {
    let mut s = String::new();
    // 进行链式调用
    File::open("hello.txt")?.read_to_string(&mut s)?;

    Ok(s)
}
```

#### ? 用于 Option的返回

```rust
fn first(arr: &[i32]) -> Option<&i32> {
   let v = arr.get(0)?;
   Some(v)
}
```

#### 常见错误

```rust
fn first(arr: &[i32]) -> Option<&i32> {
   arr.get(0)?
}
```

​`?`​ 操作符需要一个变量来承载正确的值，这个函数只会返回 `Some(&i32)`​ 或者 `None`​

* ​`let v = xxx()?;`​
* ​`xxx()?.yyy()?;`​

#### 带返回值的 main 函数

```rust
use std::error::Error;
use std::fs::File;

fn main() -> Result<(), Box<dyn Error>> {
    let f = File::open("hello.txt")?;

    Ok(())
}
```

* `Box<dyn Error>`

  * ​`std::error:Error`​ 是 Rust 中抽象层次最高的错误，其它标准库中的错误都实现了该特征，因此我们可以用该特征对象代表一切错误

### try! 避免使用

```rust
//  `?`
let x = function_with_error()?; // 若返回 Err, 则立刻返回；若返回 Ok(255)，则将 x 的值设置为 255

// `try!()`
let x = try!(function_with_error());
```

‍
